Workbook
Name ADO: #REF!
Name codigo: [1]EMMC!$J$3:$J$2747
Name FERI: "'1.- Anexo IA-SSMS'!$Z$2:$Z$17"
Name FERI26: '[2]2.- Cronograma'!$U$4:$U$19
Name FERIADO: [1]EMMC!#REF!
Name FERIADO2026: "'1.- Anexo IA-SSMS'!$Z$2:$Z$17"
Name FERIADO26: [3]Feriado!$B$3:$B$18
Name feriados2026: '[4]Consolidado Anexo Ib SIN INST'!$AM$5:$AM$15
Name FIN: [5]MNC!$AJ$6
Name INICIO: #REF!
Name ParamValues1: [6]ParamValues!$A$1:$A$14
Name PISO01: [7]N01!$B$48:$S$1608
Name PISO04: [7]N04!$C$29:$T$331
Name PISO05: [7]N05!$B$20:$S$344
Name PISO06: [7]N06!$B$19:$S$271
Name PISO07: [7]N07!$B$23:$S$249
Name PISO2: [7]N02!$B$31:$S$1335
Name PISO3: [7]N03!$B$29:$S$1101
Name TABLA: #REF!

Sheet BD
A1: Proveedor Adjudicado | B1: (Todas)
A2: Familia | B2: (Varios elementos)
C3: {=ROUND(SUMPRODUCT((C5:C1982<>"")/COUNTIF(C5:C1982,C5:C1982&"")),0)} -> 50
A4: Piso | B4: Servicio | C4: Codigo de recinto referencial | D4: Nombre Recinto | E4: Tipo Equipo/ Mobiliario | F4: Nombre | G4: Cantidad | H4: INICIO | J4: Suma de Cantidad | L4: Piso
A5: 4 | B5: Administración y apoyo general | C5: C.3.6.1.1 | D5: OFICINA JEFE GINECOLOGÍA Y OBSTETRICIA | E5: 201008 | F5: Mesa Reuniones Tipo I | G5: 1 | H5: 46220 | J5: Tipo Equipo/ Mobiliario | K5: Nombre | L5: 1 | M5: 2 | N5: 3 | O5: 4 | P5: 5 | Q5: 6 | R5: 7 | S5: Total general
A6: 4 | B6: Administración y apoyo general | C6: C.3.6.1.1 | D6: OFICINA JEFE GINECOLOGÍA Y OBSTETRICIA | E6: 201001B | F6: Escritorio en L administrativo | G6: 1 | H6: 46220 | J6: 201002 | K6: Mesa Lateral | L6: 1 | M6: 2 | N6: 2 | O6: 6 | P6: 6 | Q6: 7 | R6: 7 | S6: 31
A7: 4 | B7: Administración y apoyo general | C7: C.3.6.1.1 | D7: OFICINA JEFE GINECOLOGÍA Y OBSTETRICIA | E7: 203016A | F7: Mueble Tipo Biblioteca M45_A | G7: 1 | H7: 46220 | J7: 201003 | K7: Mesa Párvulo Inclusión | L7: 2 | S7: 2
A8: 4 | B8: Administración y apoyo general | C8: C.3.6.1.12 | D8: MÓDULO TRABAJO SUPERVISOR | E8: 201001B | F8: Escritorio en L administrativo | G8: 1 | H8: 46220 | J8: 201004 | K8: Mesa Párvulo Tipo I | L8: 3 | M8: 4 | P8: 1 | S8: 8
A9: 4 | B9: Administración y apoyo general | C9: C.3.6.1.12 | D9: MÓDULO TRABAJO SUPERVISOR | E9: 203016A | F9: Mueble Tipo Biblioteca M45_A | G9: 1 | H9: 46220 | J9: 201005 | K9: Mesa Párvulo Tipo II | L9: 12 | S9: 12
A10: 4 | B10: Administración y apoyo general | C10: C.3.6.1.2 | D10: COORDINADOR GINECOLOGÍA Y OBSTETRICIA | E10: 201001B | F10: Escritorio en L administrativo | G10: 1 | H10: 46220 | J10: 201006 | K10: Mesa Plegable | L10: 1 | S10: 1
A11: 4 | B11: Administración y apoyo general | C11: C.3.6.1.2 | D11: COORDINADOR GINECOLOGÍA Y OBSTETRICIA | E11: 203016A | F11: Mueble Tipo Biblioteca M45_A | G11: 1 | H11: 46220 | J11: 201007 | K11: Mesa Reuniones Plegable | L11: 6 | M11: 2 | S11: 8
A12: 4 | B12: Administración y apoyo general | C12: C.3.6.1.3 | D12: SALA DE ESPERA | E12: 201002 | F12: Mesa Lateral | G12: 5 | H12: 46220 | J12: 201008 | K12: Mesa Reuniones Tipo I | L12: 19 | M12: 14 | N12: 16 | O12: 2 | P12: 2 | S12: 53
A13: 4 | B13: Administración y apoyo general | C13: C.3.6.1.31.3 | D13: COORDINADOR NEONATOLOGÍA | E13: 201001B | F13: Escritorio en L administrativo | G13: 1 | H13: 46220 | J13: 201009 | K13: Mesa Reuniones Tipo II | L13: 3 | M13: 13 | N13: 1 | S13: 17
A14: 4 | B14: Administración y apoyo general | C14: C.3.6.1.31.3 | D14: COORDINADOR NEONATOLOGÍA | E14: 203016A | F14: Mueble Tipo Biblioteca M45_A | G14: 1 | H14: 46220 | J14: 201010 | K14: Mesa Reuniones Tipo III | L14: 2 | M14: 3 | N14: 5 | P14: 1 | Q14: 1 | S14: 12
A15: 4 | B15: Administración y apoyo general | C15: C.3.6.1.41.1 | D15: ESTAR PERSONAL C/ KITCHENETTE | E15: 201011B | F15: Mesa Tipo Casino Redonda 90 cm | G15: 1 | H15: 46220 | J15: 201012 | K15: Mesa Trabajo Individual | L15: 3 | S15: 3
A16: 4 | B16: Administración y apoyo general | C16: C.3.6.1.41.2 | D16: ESTAR PERSONAL C/ KITCHENETTE | E16: 201011B | F16: Mesa Tipo Casino Redonda 90 cm | G16: 1 | H16: 46220 | J16: 202001 | K16: Atril graduable | L16: 8 | S16: 8
A17: 4 | B17: Administración y apoyo general | C17: C.3.6.1.6 | D17: SALA DE ESTAR FAMILIARES Y ENTREVISTAS | E17: 201002 | F17: Mesa Lateral | G17: 1 | H17: 46220 | J17: 202002 | K17: Caja Fuerte Tipo I | L17: 6 | M17: 1 | N17: 1 | S17: 8
A18: 4 | B18: Administración y apoyo general | C18: C.3.6.1.6 | D18: SALA DE ESTAR FAMILIARES Y ENTREVISTAS | E18: 201011B | F18: Mesa Tipo Casino Redonda 90 cm | G18: 1 | H18: 46220 | J18: 202003 | K18: Caja Fuerte Tipo II | N18: 1 | S18: 1
A19: 4 | B19: Chile Crece Contigo | C19: C.3.6.1.10 | D19: SALA TALLER CHILE CRECE CONTIGO | E19: 201008 | F19: Mesa Reuniones Tipo I | G19: 1 | H19: 46220 | J19: 202004 | K19: Cama 1 1/2 Plaza | L19: 11 | S19: 11
A20: 4 | B20: Hospitalización | C20: C.3.6.1.24 | D20: SALA DE PROCEDIMIENTOS | E20: 201001E | F20: Punto de registro clínico | G20: 1 | H20: 46220 | J20: 202005 | K20: Cama 1 Plaza | L20: 1 | S20: 1
A21: 4 | B21: Hospitalización | C21: C.3.6.1.9 | D21: OFICINA CHILE CRECE CONTIGO | E21: 201001A | F21: Escritorio simple 120x70 cm | G21: 2 | H21: 46220 | J21: 202006 | K21: Cama Apilable | L21: 28 | S21: 28
A22: 4 | B22: Hospitalización | C22: C.3.6.1.9 | D22: OFICINA CHILE CRECE CONTIGO | E22: 203016A | F22: Mueble Tipo Biblioteca M45_A | G22: 2 | H22: 46220 | J22: 202007 | K22: Carro de Carga | M22: 1 | S22: 1
A23: 4 | B23: Neonatología | C23: C.3.6.1.27 | D23: SALA EXAMENES RECIÉN NACIDO | E23: 201001E | F23: Punto de registro clínico | G23: 1 | H23: 46220 | J23: 202008 | K23: Cuna Alta | L23: 14 | S23: 14
A24: 4 | B24: Neonatología | C24: C.3.6.1.30.1 | D24: SALA DE ENTREVISTAS | E24: 201001B | F24: Escritorio en L administrativo | G24: 1 | H24: 46220 | J24: 202009 | K24: Cuna Baja | L24: 14 | S24: 14
A25: 4 | B25: Neonatología | C25: C.3.6.1.30.1 | D25: SALA DE ENTREVISTAS | E25: 203016A | F25: Mueble Tipo Biblioteca M45_A | G25: 1 | H25: 46220 | J25: 202010 | K25: Escalera Tijera | L25: 4 | M25: 1 | S25: 5
A26: 4 | B26: Neonatología | C26: C.3.6.1.31.4 | D26: LACTARIO | E26: 201001E | F26: Punto de registro clínico | G26: 1 | H26: 46220 | J26: 202012 | K26: Mueble Locker | L26: 8 | S26: 8
A27: 4 | B27: Neonatología | C27: C.3.8.2.1 | D27: ESTAR PERSONAL C/ KITCHENETTE | E27: 201011B | F27: Mesa Tipo Casino Redonda 90 cm | G27: 1 | H27: 46220 | J27: 202013 | K27: Pallet | L27: 3 | S27: 3
A28: 4 | B28: SEDILE | C28: C.5.8.1.2.1 | D28: OFICINA NUTRICIONISTA | E28: 201001A | F28: Escritorio simple 120x70 cm | G28: 1 | H28: 46220 | J28: 202014 | K28: Pódium | N28: 1 | S28: 1
A29: 4 | B29: SEDILE | C29: C.5.8.1.2.1 | D29: OFICINA NUTRICIONISTA | E29: 203016A | F29: Mueble Tipo Biblioteca M45_A | G29: 1 | H29: 46220 | J29: 203001 | K29: Adaptador de llaves | L29: 1 | S29: 1
A30: 4 | B30: SEDILE | C30: C.5.8.1.2.2 | D30: ESTAR PERSONAL C/ KITCHENETTE | E30: 201011B | F30: Mesa Tipo Casino Redonda 90 cm | G30: 1 | H30: 46220 | J30: 203002 | K30: Carro Bandejero | M30: 3 | S30: 3
A31: 5 | B31: Administración y apoyo general | C31: C.3.4.2.1 | D31: SALA DE ESPERA | E31: 201002 | F31: Mesa Lateral | G31: 3 | H31: 46220 | J31: 203003 | K31: Carro de Transporte | M31: 9 | S31: 9
A32: 5 | B32: Administración y apoyo general | C32: C.3.4.2.19 | D32: ESTAR PERSONAL C/ KITCHENETTE | E32: 201011B | F32: Mesa Tipo Casino Redonda 90 cm | G32: 1 | H32: 46220 | J32: 203004 | K32: Carro de transporte alto | L32: 1 | S32: 1
A33: 5 | B33: Administración y apoyo general | C33: C.3.4.2.4 | D33: MÓDULO TRABAJO SUPERVISOR | E33: 201001A | F33: Escritorio simple 120x70 cm | G33: 3 | H33: 46220 | J33: 203005 | K33: Carro de Transporte cajas plásticas | L33: 2 | S33: 2
A34: 5 | B34: Administración y apoyo general | C34: C.3.4.2.4 | D34: MÓDULO TRABAJO SUPERVISOR | E34: 203016A | F34: Mueble Tipo Biblioteca M45_A | G34: 3 | H34: 46220 | J34: 203006 | K34: Carro de transporte pallet | L34: 1 | S34: 1
A35: 5 | B35: Administración y apoyo general | C35: C.3.4.2.9 | D35: SALA MULTIUSO | E35: 201010 | F35: Mesa Reuniones Tipo III | G35: 1 | H35: 46220 | J35: 203007 | K35: Carro dual dos ruedas | L35: 1 | S35: 1
A36: 5 | B36: Administración y apoyo general | C36: C.3.5.1 | D36: OFICINA JEFE MQ INFANTIL | E36: 201008 | F36: Mesa Reuniones Tipo I | G36: 1 | H36: 46220 | J36: 203008 | K36: Carro metálico | L36: 2 | S36: 2
A37: 5 | B37: Administración y apoyo general | C37: C.3.5.1 | D37: OFICINA JEFE MQ INFANTIL | E37: 201001B | F37: Escritorio en L administrativo | G37: 1 | H37: 46220 | J37: 203009 | K37: Carro plataforma de carga | L37: 1 | S37: 1
A38: 5 | B38: Administración y apoyo general | C38: C.3.5.1 | D38: OFICINA JEFE MQ INFANTIL | E38: 203016A | F38: Mueble Tipo Biblioteca M45_A | G38: 1 | H38: 46220 | J38: 203011 | K38: Estación de órtesis metálica | L38: 1 | S38: 1
A39: 5 | B39: Administración y apoyo general | C39: C.3.5.10 | D39: MÓDULO TRABAJO SUPERVISOR | E39: 201001A | F39: Escritorio simple 120x70 cm | G39: 1 | H39: 46220 | J39: 203012 | K39: Juego Taca - Taca | L39: 1 | M39: 1 | S39: 2
A40: 5 | B40: Administración y apoyo general | C40: C.3.5.10 | D40: MÓDULO TRABAJO SUPERVISOR | E40: 203016A | F40: Mueble Tipo Biblioteca M45_A | G40: 1 | H40: 46220 | J40: 203013 | K40: Juego Tenis de Mesa | L40: 1 | M40: 1 | S40: 2
...

Sheet Despacho_01_20260702
B2: Piso | C2: Servicio | D2: Codigo de recinto referencial | E2: Nombre Recinto | F2: Tipo Equipo/ Mobiliario | G2: Nombre | H2: Cantidad | J2: DETALLE
B3: 1 | C3: Diálisis | D3: C.2.3.1 | E3: OFICINA JEFE DIÁLISIS | F3: 201001B | G3: Escritorio en L administrativo | H3: 1 | J3: Tipo | K3: Nombre | L3: Cantidad
B4: 1 | C4: Diálisis | D4: C.2.3.1 | E4: OFICINA JEFE DIÁLISIS | F4: 203016A | G4: Mueble Tipo Biblioteca M45_A | H4: 1 | J4: 201002 | K4: Mesa Lateral | L4: 1
B5: 1 | C5: Diálisis | D5: C.2.3.12 | E5: BOX EVALUACIÓN | F5: 201001C | G5: Escritorio de Consultas | H5: 1 | J5: 201004 | K5: Mesa Párvulo Tipo I | L5: 2
B6: 1 | C6: Diálisis | D6: C.2.3.13.1 | E6: PUESTO DIALISADOS CRÓNICOS | F6: 201001A | G6: Escritorio simple 120x70 cm | H6: 1 | J6: 201008 | K6: Mesa Reuniones Tipo I | L6: 4
B7: 1 | C7: Diálisis | D7: C.2.3.13.2 | E7: PUESTO DIALISADOS CRÓNICOS | F7: 201001A | G7: Escritorio simple 120x70 cm | H7: 1 | J7: 201010 | K7: Mesa Reuniones Tipo III | L7: 1
B8: 1 | C8: Diálisis | D8: C.2.3.13.3 | E8: PUESTO DIALISADOS CRÓNICOS | F8: 201001A | G8: Escritorio simple 120x70 cm | H8: 1 | J8: 201001A | K8: Escritorio simple 120x70 cm | L8: 6
B9: 1 | C9: Diálisis | D9: C.2.3.19 | E9: SALA POST-DIALISADOS | F9: 201008 | G9: Mesa Reuniones Tipo I | H9: 1 | J9: 201001B | K9: Escritorio en L administrativo Izquierdo | L9: 8
B10: 1 | C10: Diálisis | D10: C.2.3.2 | E10: OFICINA ENFERMERA COORDINADORA (PERITONEO) | F10: 201001A | G10: Escritorio simple 120x70 cm | H10: 1 | J10: 201001B | K10: Escritorio en L administrativo Derecho | L10: 4
B11: 1 | C11: Diálisis | D11: C.2.3.2 | E11: OFICINA ENFERMERA COORDINADORA (PERITONEO) | F11: 203016A | G11: Mueble Tipo Biblioteca M45_A | H11: 1 | J11: 201001C | K11: Escritorio de Consultas | L11: 6
B12: 1 | C12: Diálisis | D12: C.2.3.39 | E12: OFICINA COORDINADORA (HEMODIALISIS) | F12: 201001B | G12: Escritorio en L administrativo | H12: 1 | J12: 201011A | K12: Mesa Tipo Casino | L12: 6
B13: 1 | C13: Diálisis | D13: C.2.3.39 | E13: OFICINA COORDINADORA (HEMODIALISIS) | F13: 203016A | G13: Mueble Tipo Biblioteca M45_A | H13: 1 | J13: 203016A | K13: Mueble Tipo Biblioteca M45_A | L13: 11
B14: 1 | C14: Diálisis | D14: C.2.3.6 | E14: MESÓN DE RECEPCIÓN C/ARCHIVO Y FOTOCOPIADORA | F14: 203016A | G14: Mueble Tipo Biblioteca M45_A | H14: 1 | J14: TOTAL | L14: =SUM(L4:L13) -> 49
B15: 1 | C15: Med física y rehabilitación | D15: C.5.7.1 | E15: MESÓN C/ARCHIVO Y FOTOCOPIADORA | F15: 203016A | G15: Mueble Tipo Biblioteca M45_A | H15: 1
B16: 1 | C16: Med física y rehabilitación | D16: C.5.7.15 | E16: GIMNASIO PEDIATRICO | F16: 201004 | G16: Mesa Párvulo Tipo I | H16: 1
B17: 1 | C17: Med física y rehabilitación | D17: C.5.7.18 | E17: SALA DE TERAPIA GRUPAL (12 MAX) | F17: 201010 | G17: Mesa Reuniones Tipo III | H17: 1
B18: 1 | C18: Med física y rehabilitación | D18: C.5.7.18 | E18: SALA DE TERAPIA GRUPAL (12 MAX) | F18: 201001A | G18: Escritorio simple 120x70 cm | H18: 1
B19: 1 | C19: Med física y rehabilitación | D19: C.5.7.19 | E19: SALA TERÁPIA OCUP. ADULTO E INFANTIL | F19: 201008 | G19: Mesa Reuniones Tipo I | H19: 3
B20: 1 | C20: Med física y rehabilitación | D20: C.5.7.19 | E20: SALA TERÁPIA OCUP. ADULTO E INFANTIL | F20: 203016A | G20: Mueble Tipo Biblioteca M45_A | H20: 1
B21: 1 | C21: Med física y rehabilitación | D21: C.5.7.20 | E21: SALA DE ACTIVDAD DE LA VIDA DIARIA C/BAÑO DE INSTRUCCIÓN | F21: 201011A | G21: Mesa Tipo Casino Circular | H21: 1
B22: 1 | C22: Med física y rehabilitación | D22: C.5.7.21 | E22: OFICINA JEFE REHABILITACIÓN | F22: 201001B | G22: Escritorio en L administrativo | H22: 1
B23: 1 | C23: Med física y rehabilitación | D23: C.5.7.21 | E23: OFICINA JEFE REHABILITACIÓN | F23: 203016A | G23: Mueble Tipo Biblioteca M45_A | H23: 1
B24: 1 | C24: Med física y rehabilitación | D24: C.5.7.22 | E24: OFICINA JEFE COORDINADOR | F24: 201001B | G24: Escritorio en L administrativo | H24: 1
B25: 1 | C25: Med física y rehabilitación | D25: C.5.7.22 | E25: OFICINA JEFE COORDINADOR | F25: 203016A | G25: Mueble Tipo Biblioteca M45_A | H25: 1
B26: 1 | C26: Med física y rehabilitación | D26: C.5.7.23 | E26: SALA MULTIUSO | F26: 203016A | G26: Mueble Tipo Biblioteca M45_A | H26: 1
B27: 1 | C27: Med física y rehabilitación | D27: C.5.7.4.1 | E27: BOX KINESIOLOGO(1) | F27: 201001C | G27: Escritorio de Consultas | H27: 1
B28: 1 | C28: Med física y rehabilitación | D28: C.5.7.4.2 | E28: BOX PSICOLOGO / A. SOCIAL | F28: 201001C | G28: Escritorio de Consultas | H28: 1
B29: 1 | C29: Med física y rehabilitación | D29: C.5.7.4.2 | E29: BOX PSICOLOGO / A. SOCIAL | F29: 203016A | G29: Mueble Tipo Biblioteca M45_A | H29: 1
B30: 1 | C30: Med física y rehabilitación | D30: C.5.7.5.1 | E30: BOX INDIFERENCIADO (FONOAUDIO Y TERAPIA OCU)(1) | F30: 201001C | G30: Escritorio de Consultas | H30: 1
B31: 1 | C31: Med física y rehabilitación | D31: C.5.7.5.2 | E31: BOX INDIFERENCIADO (FONOAUDIO Y TERAPIA OCU)(2) | F31: 201001C | G31: Escritorio de Consultas | H31: 1
B32: 1 | C32: Med física y rehabilitación | D32: C.5.7.5.2.1 | E32: BOX FONOAUDIO PEDIATRICO | F32: 201004 | G32: Mesa Párvulo Tipo I | H32: 1
B33: 1 | C33: Med física y rehabilitación | D33: C.5.7.5.2.1 | E33: BOX FONOAUDIO PEDIATRICO | F33: 201001C | G33: Escritorio de Consultas | H33: 1
B34: 1 | C34: Morgue | D34: C.5.9.2 | E34: ESPACIO PARA DEUDOS | F34: 201002 | G34: Mesa Lateral | H34: 1
B35: 1 | C35: Morgue | D35: C.5.9.5 | E35: MESÓN RECEPCIÓN DE REGISTRO DE INFORMES | F35: 201001B | G35: Escritorio en L administrativo | H35: 1
B36: 1 | C36: Morgue | D36: C.5.9.5 | E36: MESÓN RECEPCIÓN DE REGISTRO DE INFORMES | F36: 203016A | G36: Mueble Tipo Biblioteca M45_A | H36: 1
B37: 1 | C37: Morgue | D37: C.5.9.7 | E37: VESTIDOR Y ENTREGA FAMILIARES | F37: 201001A | G37: Escritorio simple 120x70 cm | H37: 1

Sheet Despacho_02_20260722
B2: Piso | C2: Servicio | D2: Codigo de recinto referencial | E2: Nombre Recinto | F2: Tipo Equipo/ Mobiliario | G2: Nombre | H2: Cantidad
B3: 1 | C3: Abastecimiento | D3: D.3.3.3.1 | E3: COORDINADOR BODEGA | F3: 201001B | G3: Escritorio en L administrativo | H3: 1 | J3: {=+_xlfn.UNIQUE(G3:G127)} -> Escritorio en L administrativo | K3: =+_xlfn.XLOOKUP(J3,$G$3:$G$127,$F$3:$F$127) -> 201001B | L3: =+SUMIF($G$3:$G$127,J3,$H$3:$H$127) -> 28
B4: 1 | C4: Abastecimiento | D4: D.3.3.3.1 | E4: COORDINADOR BODEGA | F4: 203016A | G4: Mueble Tipo Biblioteca M45_A | H4: 1 | J4: Mueble Tipo Biblioteca M45_A | K4: =+_xlfn.XLOOKUP(J4,$G$3:$G$127,$F$3:$F$127) -> 203016A | L4: =+SUMIF($G$3:$G$127,J4,$H$3:$H$127) -> 54
B5: 1 | C5: Abastecimiento | D5: D.3.3.3.10 | E5: ESTAR PERSONAL C/ KITCHENETTE | F5: 201011A | G5: Mesa Tipo Casino Circular | H5: 1 | J5: Mesa Tipo Casino Circular | K5: =+_xlfn.XLOOKUP(J5,$G$3:$G$127,$F$3:$F$127) -> 201011A | L5: =+SUMIF($G$3:$G$127,J5,$H$3:$H$127) -> 9
B6: 1 | C6: Abastecimiento | D6: D.3.3.3.11 | E6: ÁREA REGISTRO BODEGA GENERAL | F6: 201001A | G6: Escritorio simple 120x70 cm | H6: 1 | J6: Escritorio simple 120x70 cm | K6: =+_xlfn.XLOOKUP(J6,$G$3:$G$127,$F$3:$F$127) -> 201001A | L6: =+SUMIF($G$3:$G$127,J6,$H$3:$H$127) -> 31
B7: 1 | C7: Abastecimiento | D7: D.3.3.3.11 | E7: ÁREA REGISTRO BODEGA GENERAL | F7: 203016A | G7: Mueble Tipo Biblioteca M45_A | H7: 1 | J7: Mesa Reuniones Tipo I | K7: =+_xlfn.XLOOKUP(J7,$G$3:$G$127,$F$3:$F$127) -> 201008 | L7: =+SUMIF($G$3:$G$127,J7,$H$3:$H$127) -> 10
B8: 1 | C8: Abastecimiento | D8: D.3.3.3.2 | E8: MESÓN DE RECEPCIÓN C/ARCHIVO Y FOTOCOPIADORA | F8: 203016A | G8: Mueble Tipo Biblioteca M45_A | H8: 1 | J8: Escritorio de Consultas | K8: =+_xlfn.XLOOKUP(J8,$G$3:$G$127,$F$3:$F$127) -> 201001C | L8: =+SUMIF($G$3:$G$127,J8,$H$3:$H$127) -> 7
B9: 1 | C9: Abastecimiento | D9: D.3.3.3.22 | E9: ÁREA REGISTRO BODEGA FARMACIA E INSUMOS | F9: 201001A | G9: Escritorio simple 120x70 cm | H9: 1 | J9: Mesa Lateral | K9: =+_xlfn.XLOOKUP(J9,$G$3:$G$127,$F$3:$F$127) -> 201002 | L9: =+SUMIF($G$3:$G$127,J9,$H$3:$H$127) -> 1
B10: 1 | C10: Abastecimiento | D10: D.3.3.3.22 | E10: ÁREA REGISTRO BODEGA FARMACIA E INSUMOS | F10: 203016A | G10: Mueble Tipo Biblioteca M45_A | H10: 1 | J10: Mesa Párvulo Tipo II | K10: =+_xlfn.XLOOKUP(J10,$G$3:$G$127,$F$3:$F$127) -> 201005 | L10: =+SUMIF($G$3:$G$127,J10,$H$3:$H$127) -> 12
B11: 1 | C11: Consultas medicas generales | D11: A.1.3 | E11: OFICINA INTERCULTURAL | F11: 201001B | G11: Escritorio en L administrativo | H11: 1 | J11: Mueble Locker | K11: =+_xlfn.XLOOKUP(J11,$G$3:$G$127,$F$3:$F$127) -> 202012 | L11: =+SUMIF($G$3:$G$127,J11,$H$3:$H$127) -> 8
B12: 1 | C12: Consultas medicas generales | D12: A.1.3 | E12: OFICINA INTERCULTURAL | F12: 203016A | G12: Mueble Tipo Biblioteca M45_A | H12: 1 | J12: Mesa Párvulo Inclusión | K12: =+_xlfn.XLOOKUP(J12,$G$3:$G$127,$F$3:$F$127) -> 201003 | L12: =+SUMIF($G$3:$G$127,J12,$H$3:$H$127) -> 2
B13: 1 | C13: Consultas medicas generales | D13: A.1.5 | E13: OFICINA COMPIN | F13: 201008 | G13: Mesa Reuniones Tipo I | H13: 1 | J13: Mesa Párvulo Tipo I | K13: =+_xlfn.XLOOKUP(J13,$G$3:$G$127,$F$3:$F$127) -> 201004 | L13: =+SUMIF($G$3:$G$127,J13,$H$3:$H$127) -> 1
B14: 1 | C14: Consultas medicas generales | D14: A.1.5 | E14: OFICINA COMPIN | F14: 201001B | G14: Escritorio en L administrativo | H14: 1 | J14: Mesa Reuniones Tipo III | K14: =+_xlfn.XLOOKUP(J14,$G$3:$G$127,$F$3:$F$127) -> 201010 | L14: =+SUMIF($G$3:$G$127,J14,$H$3:$H$127) -> 1
B15: 1 | C15: Consultas medicas generales | D15: A.1.5 | E15: OFICINA COMPIN | F15: 203016A | G15: Mueble Tipo Biblioteca M45_A | H15: 1 | J15: Mesa Reuniones Tipo II | K15: =+_xlfn.XLOOKUP(J15,$G$3:$G$127,$F$3:$F$127) -> 201009 | L15: =+SUMIF($G$3:$G$127,J15,$H$3:$H$127) -> 2
B16: 1 | C16: Consultas medicas generales | D16: A.1.6 | E16: OFICINA FONASA | F16: 201008 | G16: Mesa Reuniones Tipo I | H16: 1 | J16: TOTAL | L16: =SUM(L3:L15) -> 166
B17: 1 | C17: Consultas medicas generales | D17: A.1.6 | E17: OFICINA FONASA | F17: 201001B | G17: Escritorio en L administrativo | H17: 1
B18: 1 | C18: Consultas medicas generales | D18: A.1.6 | E18: OFICINA FONASA | F18: 203016A | G18: Mueble Tipo Biblioteca M45_A | H18: 1
B19: 1 | C19: Consultas medicas generales | D19: B.3.1.1 | E19: OFICINA JEFE OIRS | F19: 201008 | G19: Mesa Reuniones Tipo I | H19: 1
B20: 1 | C20: Consultas medicas generales | D20: B.3.1.1 | E20: OFICINA JEFE OIRS | F20: 201001B | G20: Escritorio en L administrativo | H20: 1
B21: 1 | C21: Consultas medicas generales | D21: B.3.1.1 | E21: OFICINA JEFE OIRS | F21: 203016A | G21: Mueble Tipo Biblioteca M45_A | H21: 1
B22: 1 | C22: Consultas medicas generales | D22: C.1.2.1 | E22: MÓD. DE TRABAJO PROFESIONALES (gestión de la demanda) | F22: 201008 | G22: Mesa Reuniones Tipo I | H22: 1
B23: 1 | C23: Consultas medicas generales | D23: C.1.2.1 | E23: MÓD. DE TRABAJO PROFESIONALES (gestión de la demanda) | F23: 201001B | G23: Escritorio en L administrativo | H23: 1
B24: 1 | C24: Consultas medicas generales | D24: C.1.2.1 | E24: MÓD. DE TRABAJO PROFESIONALES (gestión de la demanda) | F24: 203016A | G24: Mueble Tipo Biblioteca M45_A | H24: 1
B25: 1 | C25: Consultas medicas generales | D25: C.1.2.1.1 | E25: MÓDULO DE TRABAJO PROFESIONALES GES | F25: 201001A | G25: Escritorio simple 120x70 cm | H25: 1
B26: 1 | C26: Consultas medicas generales | D26: C.1.2.1.2 | E26: MÓDULO DE TRABAJO PROFESIONALES LISTA DE ESPERA | F26: 201001A | G26: Escritorio simple 120x70 cm | H26: 1
B27: 1 | C27: Consultas medicas generales | D27: C.1.2.1.3 | E27: MÓD. DE TRABAJO PROFESIONALES (gestión de la demanda) | F27: 201001A | G27: Escritorio simple 120x70 cm | H27: 1
B28: 1 | C28: Consultas medicas generales | D28: C.1.2.1.3 | E28: MÓD. DE TRABAJO PROFESIONALES (gestión de la demanda) | F28: 203016A | G28: Mueble Tipo Biblioteca M45_A | H28: 1
B29: 1 | C29: Consultas medicas generales | D29: C.1.2.2 | E29: MÓDULO DE TRABAJO ADMINISTRATIVOS GES | F29: 201008 | G29: Mesa Reuniones Tipo I | H29: 1
B30: 1 | C30: Consultas medicas generales | D30: C.1.2.2 | E30: MÓDULO DE TRABAJO ADMINISTRATIVOS GES | F30: 201001A | G30: Escritorio simple 120x70 cm | H30: 3
B31: 1 | C31: Consultas medicas generales | D31: C.1.2.2 | E31: MÓDULO DE TRABAJO ADMINISTRATIVOS GES | F31: 203016A | G31: Mueble Tipo Biblioteca M45_A | H31: 3
B32: 1 | C32: Consultas medicas generales | D32: C.1.2.2.1 | E32: MÓDULO DE TRABAJO ADMINISTRATIVOS MANTENCIÓN DE AGENDA | F32: 201001B | G32: Escritorio en L administrativo | H32: 2
B33: 1 | C33: Consultas medicas generales | D33: C.1.2.2.1 | E33: MÓDULO DE TRABAJO ADMINISTRATIVOS MANTENCIÓN DE AGENDA | F33: 203016A | G33: Mueble Tipo Biblioteca M45_A | H33: 2
B34: 1 | C34: Consultas medicas generales | D34: C.1.2.2.2 | E34: MÓDULO DE TRABAJO ADMINISTRATIVOS LISTA DE ESPERA | F34: 201001B | G34: Escritorio en L administrativo | H34: 2
B35: 1 | C35: Consultas medicas generales | D35: C.1.2.2.2 | E35: MÓDULO DE TRABAJO ADMINISTRATIVOS LISTA DE ESPERA | F35: 203016A | G35: Mueble Tipo Biblioteca M45_A | H35: 2
B36: 1 | C36: Consultas medicas generales | D36: D.1.1.1.1 | E36: OFICINA JEFE SOME | F36: 201008 | G36: Mesa Reuniones Tipo I | H36: 1
B37: 1 | C37: Consultas medicas generales | D37: D.1.1.1.1 | E37: OFICINA JEFE SOME | F37: 201001B | G37: Escritorio en L administrativo | H37: 1
B38: 1 | C38: Consultas medicas generales | D38: D.1.1.1.1 | E38: OFICINA JEFE SOME | F38: 203016A | G38: Mueble Tipo Biblioteca M45_A | H38: 1
B39: 1 | C39: Consultas medicas generales | D39: D.1.1.1.2 | E39: SECRETARIA C/ARCH. Y FOTO | F39: 201001B | G39: Escritorio en L administrativo | H39: 1
B40: 1 | C40: Consultas medicas generales | D40: D.1.1.1.2 | E40: SECRETARIA C/ARCH. Y FOTO | F40: 203016A | G40: Mueble Tipo Biblioteca M45_A | H40: 1
B41: 1 | C41: Consultas medicas generales | D41: D.1.1.1.3 | E41: MODULOS DE TRABAJO (OPERADOR TELEFONICO) | F41: 201001A | G41: Escritorio simple 120x70 cm | H41: 2
...

Sheet Despacho_03_20260728
B1: Proveedor Adjudicado | C1: (Varios elementos)
B2: Familia | C2: (Varios elementos)
D3: {=ROUND(SUMPRODUCT((D5:D1982<>"")/COUNTIF(D5:D1982,D5:D1982&"")),0)} -> 154
B4: Piso | C4: Servicio | D4: Codigo de recinto referencial | E4: Nombre Recinto | F4: Tipo Equipo/ Mobiliario | G4: Nombre | H4: Cantidad
B5: 2 | C5: Biblioteca | D5: C.2.6.2.2 | E5: SALA DE REUNIONES | F5: 201010 | G5: Mesa Reuniones Tipo III | H5: 1 | J5: {=+_xlfn.UNIQUE(G5:G239)} -> Mesa Reuniones Tipo III | K5: =+_xlfn.XLOOKUP(J5,$G$5:$G$239,$F$5:$F$239) -> 201010 | L5: =+SUMIF($G$3:$G$239,J5,$H$3:$H$239) -> 3
B6: 2 | C6: Biblioteca | D6: E.2.3.1 | E6: SALA TRABAJO GRUPAL | F6: 201009 | G6: Mesa Reuniones Tipo II | H6: 1 | J6: Mesa Reuniones Tipo II | K6: =+_xlfn.XLOOKUP(J6,$G$5:$G$239,$F$5:$F$239) -> 201009 | L6: =+SUMIF($G$3:$G$239,J6,$H$3:$H$239) -> 13
B7: 2 | C7: Biblioteca | D7: E.2.3.2 | E7: SALA TRABAJO GRUPAL | F7: 201009 | G7: Mesa Reuniones Tipo II | H7: 1 | J7: Mesa Reuniones Tipo I | K7: =+_xlfn.XLOOKUP(J7,$G$5:$G$239,$F$5:$F$239) -> 201008 | L7: =+SUMIF($G$3:$G$239,J7,$H$3:$H$239) -> 14
B8: 2 | C8: Biblioteca | D8: E.2.4 | E8: SALA DE LECTURA | F8: 201008 | G8: Mesa Reuniones Tipo I | H8: 3 | J8: Mesa Tipo Casino Redonda 90 cm | K8: =+_xlfn.XLOOKUP(J8,$G$5:$G$239,$F$5:$F$239) -> 201011B | L8: =+SUMIF($G$3:$G$239,J8,$H$3:$H$239) -> 13
B9: 2 | C9: Cafetería | D9: A.1.7.2 | E9: CAFETERÍA | F9: 201011B | G9: Mesa Tipo Casino Redonda 90 cm | H9: 8 | J9: Escritorio en L administrativo | K9: =+_xlfn.XLOOKUP(J9,$G$5:$G$239,$F$5:$F$239) -> 201001B | L9: =+SUMIF($G$3:$G$239,J9,$H$3:$H$239) -> 47
B10: 2 | C10: Central de Alimentación | D10: C.5.8.1.1.1 | E10: OFICINA JEFE NUTRICIONISTA | F10: 201001B | G10: Escritorio en L administrativo | H10: 1 | J10: Mueble Tipo Biblioteca M45_A | K10: =+_xlfn.XLOOKUP(J10,$G$5:$G$239,$F$5:$F$239) -> 203016A | L10: =+SUMIF($G$3:$G$239,J10,$H$3:$H$239) -> 76
B11: 2 | C11: Central de Alimentación | D11: C.5.8.1.1.1 | E11: OFICINA JEFE NUTRICIONISTA | F11: 203016A | G11: Mueble Tipo Biblioteca M45_A | H11: 1 | J11: Punto de registro clínico | K11: =+_xlfn.XLOOKUP(J11,$G$5:$G$239,$F$5:$F$239) -> 201001E | L11: =+SUMIF($G$3:$G$239,J11,$H$3:$H$239) -> 21
B12: 2 | C12: Central de Alimentación | D12: C.5.8.1.1.2 | E12: MÓDULO DE TRABAJO (INFORMES) | F12: 201001B | G12: Escritorio en L administrativo | H12: 4 | J12: Mesa Tipo Casino Circular | K12: =+_xlfn.XLOOKUP(J12,$G$5:$G$239,$F$5:$F$239) -> 201011A | L12: =+SUMIF($G$3:$G$239,J12,$H$3:$H$239) -> 57
B13: 2 | C13: Central de Alimentación | D13: C.5.8.1.1.2 | E13: MÓDULO DE TRABAJO (INFORMES) | F13: 203016A | G13: Mueble Tipo Biblioteca M45_A | H13: 4 | J13: Escritorio de Consultas | K13: =+_xlfn.XLOOKUP(J13,$G$5:$G$239,$F$5:$F$239) -> 201001C | L13: =+SUMIF($G$3:$G$239,J13,$H$3:$H$239) -> 40
B14: 2 | C14: Central de Alimentación | D14: C.5.8.1.1.5 | E14: SECRETARIA C/ARCH. Y FOTO | F14: 201001B | G14: Escritorio en L administrativo | H14: 1 | J14: Escritorio simple 120x70 cm | K14: =+_xlfn.XLOOKUP(J14,$G$5:$G$239,$F$5:$F$239) -> 201001A | L14: =+SUMIF($G$3:$G$239,J14,$H$3:$H$239) -> 52
B15: 2 | C15: Central de Alimentación | D15: C.5.8.1.1.5 | E15: SECRETARIA C/ARCH. Y FOTO | F15: 203016A | G15: Mueble Tipo Biblioteca M45_A | H15: 1 | J15: Escritorio simple 130x70 cm | K15: =+_xlfn.XLOOKUP(J15,$G$5:$G$239,$F$5:$F$239) -> 201001D | L15: =+SUMIF($G$3:$G$239,J15,$H$3:$H$239) -> 4
B16: 2 | C16: Central de Alimentación | D16: C.5.8.2.1 | E16: JEFE CENTRAL DE ALIMENTACIÓN | F16: 201001B | G16: Escritorio en L administrativo | H16: 1 | J16: Mueble Tipo Biblioteca M45_B | K16: =+_xlfn.XLOOKUP(J16,$G$5:$G$239,$F$5:$F$239) -> 203016B | L16: =+SUMIF($G$3:$G$239,J16,$H$3:$H$239) -> 16
B17: 2 | C17: Central de Alimentación | D17: C.5.8.2.1 | E17: JEFE CENTRAL DE ALIMENTACIÓN | F17: 203016A | G17: Mueble Tipo Biblioteca M45_A | H17: 1 | J17: Mesa Lateral | K17: =+_xlfn.XLOOKUP(J17,$G$5:$G$239,$F$5:$F$239) -> 201002 | L17: =+SUMIF($G$3:$G$239,J17,$H$3:$H$239) -> 2
B18: 2 | C18: Central de Alimentación | D18: C.5.8.2.14 | E18: BODEGA DIARIA ALIMENTOS NO PERECIBLES (ABARROTES) | F18: 201001E | G18: Punto de registro clínico | H18: 1 | J18: Mesa Párvulo Tipo I | K18: =+_xlfn.XLOOKUP(J18,$G$5:$G$239,$F$5:$F$239) -> 201004 | L18: =+SUMIF($G$3:$G$239,J18,$H$3:$H$239) -> 4
B19: 2 | C19: Central de Alimentación | D19: C.5.8.2.2 | E19: SECRETARIA C/ARCH. Y FOTO | F19: 201001B | G19: Escritorio en L administrativo | H19: 1 | J19: TOTAL | L19: =SUM(L5:L18) -> 362
B20: 2 | C20: Central de Alimentación | D20: C.5.8.2.2 | E20: SECRETARIA C/ARCH. Y FOTO | F20: 203016A | G20: Mueble Tipo Biblioteca M45_A | H20: 1
B21: 2 | C21: Central de Alimentación | D21: C.5.8.2.24 | E21: OFICINA SUPERVISORA | F21: 201001B | G21: Escritorio en L administrativo | H21: 1
B22: 2 | C22: Central de Alimentación | D22: C.5.8.2.24 | E22: OFICINA SUPERVISORA | F22: 203016A | G22: Mueble Tipo Biblioteca M45_A | H22: 1
B23: 2 | C23: Central de Alimentación | D23: C.5.8.2.33 | E23: PREP. DE BANDEJAS, MONTAJE DE CARROS Y DESP. | F23: 201001E | G23: Punto de registro clínico | H23: 1
B24: 2 | C24: Central de Alimentación | D24: C.5.8.2.7 | E24: ESTAR PERSONAL C/ KITCHENETTE | F24: 201011A | G24: Mesa Tipo Casino Circular | H24: 1
B25: 2 | C25: Central de Alimentación | D25: E.5.1.1 | E25: SALA MULTIUSO (labores administrativas) | F25: 201008 | G25: Mesa Reuniones Tipo I | H25: 1
B26: 2 | C26: Central de Alimentación | D26: E.5.1.1 | E26: SALA MULTIUSO (labores administrativas) | F26: 201001B | G26: Escritorio en L administrativo | H26: 1
B27: 2 | C27: Central de Alimentación | D27: E.5.1.1 | E27: SALA MULTIUSO (labores administrativas) | F27: 203016A | G27: Mueble Tipo Biblioteca M45_A | H27: 1
B28: 2 | C28: Comedor para funcionarios y público | D28: E.3.5 | E28: COMEDORES PARA FUNCIONARIOS | F28: 201011A | G28: Mesa Tipo Casino Circular | H28: 56
B29: 2 | C29: Comedor para funcionarios y público | D29: E.3.8 | E29: OFICINA ADMINISTRADOR | F29: 201001B | G29: Escritorio en L administrativo | H29: 1
B30: 2 | C30: Comedor para funcionarios y público | D30: E.3.8 | E30: OFICINA ADMINISTRADOR | F30: 203016A | G30: Mueble Tipo Biblioteca M45_A | H30: 1
B31: 2 | C31: Consultas Ambulatorias | D31: D.1.2.1 | E31: SECRETARIA C/ARCHIVO, FOTOCOP. | F31: 201001B | G31: Escritorio en L administrativo | H31: 1
B32: 2 | C32: Consultas Ambulatorias | D32: D.1.2.1 | E32: SECRETARIA C/ARCHIVO, FOTOCOP. | F32: 203016A | G32: Mueble Tipo Biblioteca M45_A | H32: 1
B33: 2 | C33: Consultas Ambulatorias | D33: D.1.2.2 | E33: OFICINA JEFE TIC | F33: 201008 | G33: Mesa Reuniones Tipo I | H33: 1
B34: 2 | C34: Consultas Ambulatorias | D34: D.1.2.2 | E34: OFICINA JEFE TIC | F34: 201001B | G34: Escritorio en L administrativo | H34: 1
B35: 2 | C35: Consultas Ambulatorias | D35: D.1.2.2 | E35: OFICINA JEFE TIC | F35: 203016A | G35: Mueble Tipo Biblioteca M45_A | H35: 1
B36: 2 | C36: Consultas Ambulatorias | D36: D.1.2.3 | E36: MÓDULOS DE TRABAJO DESARROLLO Y MANTENCIÓN | F36: 201001B | G36: Escritorio en L administrativo | H36: 3
B37: 2 | C37: Consultas Ambulatorias | D37: D.1.2.3 | E37: MÓDULOS DE TRABAJO DESARROLLO Y MANTENCIÓN | F37: 203016A | G37: Mueble Tipo Biblioteca M45_A | H37: 3
B38: 2 | C38: Consultas Ambulatorias | D38: D.4.4.1.2 | E38: COORDINADOR SALUD DEL TRABAJADOR | F38: 201001B | G38: Escritorio en L administrativo | H38: 1
B39: 2 | C39: Consultas Ambulatorias | D39: D.4.4.1.2 | E39: COORDINADOR SALUD DEL TRABAJADOR | F39: 203016A | G39: Mueble Tipo Biblioteca M45_A | H39: 1
B40: 2 | C40: Consultas Ambulatorias | D40: D.4.4.1.3.1 | E40: BOX DE ATENCIÓN | F40: 201001C | G40: Escritorio de Consultas | H40: 1
...

Sheet Despacho_04_20260728
B1: Proveedor Adjudicado | C1: (Varios elementos)
B2: Familia | C2: (Varios elementos)
D3: {=ROUND(SUMPRODUCT((D5:D1982<>"")/COUNTIF(D5:D1982,D5:D1982&"")),0)} -> 99
B4: Piso | C4: Servicio | D4: Codigo de recinto referencial | E4: Nombre Recinto | F4: Tipo Equipo/ Mobiliario | G4: Nombre | H4: Cantidad
B5: 3 | C5: Administración y apoyo general | D5: B.1.1 | E5: SECRETARÍA C/ARCHIVO Y FOTOCOPIADORA | F5: 201001B | G5: Escritorio en L administrativo | H5: 1 | K5: Escritorio en L administrativo | L5: 201001B | M5: =+SUMIF($G$3:$G$239,K5,$H$3:$H$239) -> 82
B6: 3 | C6: Administración y apoyo general | D6: B.1.1 | E6: SECRETARÍA C/ARCHIVO Y FOTOCOPIADORA | F6: 203016A | G6: Mueble Tipo Biblioteca M45_A | H6: 1 | K6: Mueble Tipo Biblioteca M45_A | L6: 203016A | M6: =+SUMIF($G$3:$G$239,K6,$H$3:$H$239) -> 102
B7: 3 | C7: Administración y apoyo general | D7: B.1.3 | E7: OFICINA DIRECTOR C/BAÑO | F7: 201008 | G7: Mesa Reuniones Tipo I | H7: 1 | K7: Mesa Reuniones Tipo I | L7: 201008 | M7: =+SUMIF($G$3:$G$239,K7,$H$3:$H$239) -> 16
B8: 3 | C8: Administración y apoyo general | D8: B.1.3 | E8: OFICINA DIRECTOR C/BAÑO | F8: 201001B | G8: Escritorio en L administrativo | H8: 1 | K8: Escritorio simple 120x70 cm | L8: 201001A | M8: =+SUMIF($G$3:$G$239,K8,$H$3:$H$239) -> 20
B9: 3 | C9: Administración y apoyo general | D9: B.1.3 | E9: OFICINA DIRECTOR C/BAÑO | F9: 203016A | G9: Mueble Tipo Biblioteca M45_A | H9: 1 | K9: Mesa Reuniones Tipo III | L9: 201010 | M9: =+SUMIF($G$3:$G$239,K9,$H$3:$H$239) -> 5
B10: 3 | C10: Administración y apoyo general | D10: B.2.1.1 | E10: SECRETARÍA C/ARCHIVO Y FOTOCOP. | F10: 203016A | G10: Mueble Tipo Biblioteca M45_A | H10: 2 | K10: Punto de registro clínico | L10: 201001E | M10: =+SUMIF($G$3:$G$239,K10,$H$3:$H$239) -> 10
B11: 3 | C11: Administración y apoyo general | D11: B.2.1.2 | E11: SECRETARÍA C/ARCHIVO Y FOTOCOP. | F11: 203016A | G11: Mueble Tipo Biblioteca M45_A | H11: 2 | K11: Mesa Tipo Casino Redonda 90 cm | L11: 201011B | M11: =+SUMIF($G$3:$G$239,K11,$H$3:$H$239) -> 4
B12: 3 | C12: Administración y apoyo general | D12: B.2.2 | E12: OFICINA SUBDIRECTOR ADMINISTRATIVO | F12: 201008 | G12: Mesa Reuniones Tipo I | H12: 1 | K12: Mesa Reuniones Tipo II | L12: 201009 | M12: =+SUMIF($G$3:$G$239,K12,$H$3:$H$239) -> 1
B13: 3 | C13: Administración y apoyo general | D13: B.2.2 | E13: OFICINA SUBDIRECTOR ADMINISTRATIVO | F13: 201001B | G13: Escritorio en L administrativo | H13: 1 | K13: Mesa Tipo Casino Circular | L13: 201011A | M13: =+SUMIF($G$3:$G$239,K13,$H$3:$H$239) -> 2
B14: 3 | C14: Administración y apoyo general | D14: B.2.2 | E14: OFICINA SUBDIRECTOR ADMINISTRATIVO | F14: 203016A | G14: Mueble Tipo Biblioteca M45_A | H14: 1 | K14: Mesa Lateral | L14: 201002 | M14: =+SUMIF($G$3:$G$239,K14,$H$3:$H$239) -> 2
B15: 3 | C15: Administración y apoyo general | D15: B.2.3 | E15: OFICINA SUBDIRECTOR MÉDICO | F15: 201008 | G15: Mesa Reuniones Tipo I | H15: 1 | K15: TOTAL | M15: =SUM(M5:M14) -> 244
B16: 3 | C16: Administración y apoyo general | D16: B.2.3 | E16: OFICINA SUBDIRECTOR MÉDICO | F16: 201001B | G16: Escritorio en L administrativo | H16: 1
B17: 3 | C17: Administración y apoyo general | D17: B.2.3 | E17: OFICINA SUBDIRECTOR MÉDICO | F17: 203016A | G17: Mueble Tipo Biblioteca M45_A | H17: 1
B18: 3 | C18: Administración y apoyo general | D18: B.3.2.1 | E18: OF. JEFE CONTROL DE GESTIÓN | F18: 201008 | G18: Mesa Reuniones Tipo I | H18: 1
B19: 3 | C19: Administración y apoyo general | D19: B.3.2.1 | E19: OF. JEFE CONTROL DE GESTIÓN | F19: 201001B | G19: Escritorio en L administrativo | H19: 1
B20: 3 | C20: Administración y apoyo general | D20: B.3.2.1 | E20: OF. JEFE CONTROL DE GESTIÓN | F20: 203016A | G20: Mueble Tipo Biblioteca M45_A | H20: 1
B21: 3 | C21: Administración y apoyo general | D21: B.3.2.2 | E21: SECRETARÍA C/ARCHIVO Y FOTOCO. | F21: 201001B | G21: Escritorio en L administrativo | H21: 1
B22: 3 | C22: Administración y apoyo general | D22: B.3.2.2 | E22: SECRETARÍA C/ARCHIVO Y FOTOCO. | F22: 203016A | G22: Mueble Tipo Biblioteca M45_A | H22: 1
B23: 3 | C23: Administración y apoyo general | D23: B.3.2.3 | E23: MÓD. DE TRABAJO (GRD profesionales + administrativo) | F23: 201001B | G23: Escritorio en L administrativo | H23: 4
B24: 3 | C24: Administración y apoyo general | D24: B.3.2.3 | E24: MÓD. DE TRABAJO (GRD profesionales + administrativo) | F24: 203016A | G24: Mueble Tipo Biblioteca M45_A | H24: 4
B25: 3 | C25: Administración y apoyo general | D25: B.3.2.4 | E25: MÓD. TRABAJO (Winsig) | F25: 201001B | G25: Escritorio en L administrativo | H25: 1
B26: 3 | C26: Administración y apoyo general | D26: B.3.2.4 | E26: MÓD. TRABAJO (Winsig) | F26: 203016A | G26: Mueble Tipo Biblioteca M45_A | H26: 1
B27: 3 | C27: Administración y apoyo general | D27: B.3.3.1 | E27: SECRETARIA C/ARCHIVO, FOTOCOP. | F27: 201001B | G27: Escritorio en L administrativo | H27: 1
B28: 3 | C28: Administración y apoyo general | D28: B.3.3.1 | E28: SECRETARIA C/ARCHIVO, FOTOCOP. | F28: 203016A | G28: Mueble Tipo Biblioteca M45_A | H28: 1
B29: 3 | C29: Administración y apoyo general | D29: B.3.3.2 | E29: MÓD. TRABAJO (calidad) | F29: 201001B | G29: Escritorio en L administrativo | H29: 3
B30: 3 | C30: Administración y apoyo general | D30: B.3.3.2 | E30: MÓD. TRABAJO (calidad) | F30: 203016A | G30: Mueble Tipo Biblioteca M45_A | H30: 3
... B36: 3 | C36: Administración y apoyo general | D36: B.3.5.1 | E36: OFICINA ASESOR JURÍDICO | F36: 203016A | G36: Mueble Tipo Biblioteca M45_A | H36: 1
B37: 3 | C37: Administración y apoyo general | D37: B.3.6.1 | E37: OFICINA JEFE AUDITORIA | F37: 201008 | G37: Mesa Reuniones Tipo I | H37: 1
B38: 3 | C38: Administración y apoyo general | D38: B.3.6.1 | E38: OFICINA JEFE AUDITORIA | F38: 201001B | G38: Escritorio en L administrativo | H38: 1
B39: 3 | C39: Administración y apoyo general | D39: B.3.6.1 | E39: OFICINA JEFE AUDITORIA | F39: 203016A | G39: Mueble Tipo Biblioteca M45_A | H39: 1
B40: 3 | C40: Administración y apoyo general | D40: B.3.7.2 | E40: MÓD. DE TRABAJO | F40: 201001A | G40: Escritorio simple 120x70 cm | H40: 1
B41: 3 | C41: Administración y apoyo general | D41: B.3.7.2 | E41: MÓD. DE TRABAJO | F41: 203016A | G41: Mueble Tipo Biblioteca M45_A | H41: 1
B42: 3 | C42: Administración y apoyo general | D42: B.4.1 | E42: COORDINADOR GESTIÓN DEL CUIDADO AT. ABIERTA | F42: 201001B | G42: Escritorio en L administrativo | H42: 2
B43: 3 | C43: Administración y apoyo general | D43: B.4.1 | E43: COORDINADOR GESTIÓN DEL CUIDADO AT. ABIERTA | F43: 203016A | G43: Mueble Tipo Biblioteca M45_A | H43: 2
B44: 3 | C44: Administración y apoyo general | D44: B.4.2 | E44: COORDINADOR GESTIÓN DEL CUIDADO AT. CERRADA | F44: 201001B | G44: Escritorio en L administrativo | H44: 1
B45: 3 | C45: Administración y apoyo general | D45: B.4.2 | E45: COORDINADOR GESTIÓN DEL CUIDADO AT. CERRADA | F45: 203016A | G45: Mueble Tipo Biblioteca M45_A | H45: 1
...

Sheet Despacho_05_20260810
B2: Piso | C2: Servicio | D2: Codigo de recinto referencial | E2: Nombre Recinto | F2: Tipo Equipo/ Mobiliario | G2: Nombre | H2: Cantidad | J2: DETALLE
B3: 4 | C3: Administración y apoyo general | D3: C.3.6.1.1 | E3: OFICINA JEFE GINECOLOGÍA Y OBSTETRICIA | F3: 201008 | G3: Mesa Reuniones Tipo I | H3: 1 | J3: Tipo | K3: Nombre | L3: Cantidad
B4: 4 | C4: Administración y apoyo general | D4: C.3.6.1.1 | E4: OFICINA JEFE GINECOLOGÍA Y OBSTETRICIA | F4: 201001B | G4: Escritorio en L administrativo | H4: 1 | J4: 201008 | K4: Mesa Reuniones Tipo I | L4: =+SUMIF($F$3:$F$239,J4,$H$3:$H$239) -> 4
B5: 4 | C5: Administración y apoyo general | D5: C.3.6.1.1 | E5: OFICINA JEFE GINECOLOGÍA Y OBSTETRICIA | F5: 203016A | G5: Mueble Tipo Biblioteca M45_A | H5: 1 | J5: 201001B | K5: Escritorio en L administrativo | L5: =+SUMIF($F$3:$F$239,J5,$H$3:$H$239) -> 10
B6: 4 | C6: Administración y apoyo general | D6: C.3.6.1.12 | E6: MÓDULO TRABAJO SUPERVISOR | F6: 201001B | G6: Escritorio en L administrativo | H6: 1 | J6: 203016A | K6: Mueble Tipo Biblioteca M45_A | L6: =+SUMIF($F$3:$F$239,J6,$H$3:$H$239) -> 21
B7: 4 | C7: Administración y apoyo general | D7: C.3.6.1.12 | E7: MÓDULO TRABAJO SUPERVISOR | F7: 203016A | G7: Mueble Tipo Biblioteca M45_A | H7: 1 | J7: 201002 | K7: Mesa Lateral | L7: =+SUMIF($F$3:$F$239,J7,$H$3:$H$239) -> 26
B8: 4 | C8: Administración y apoyo general | D8: C.3.6.1.2 | E8: COORDINADOR GINECOLOGÍA Y OBSTETRICIA | F8: 201001B | G8: Escritorio en L administrativo | H8: 1 | J8: 201001A | K8: Escritorio simple 120x70 cm | L8: =+SUMIF($F$3:$F$239,J8,$H$3:$H$239) -> 13
B9: 4 | C9: Administración y apoyo general | D9: C.3.6.1.2 | E9: COORDINADOR GINECOLOGÍA Y OBSTETRICIA | F9: 203016A | G9: Mueble Tipo Biblioteca M45_A | H9: 1 | J9: 201010 | K9: Mesa Reuniones Tipo III | L9: =+SUMIF($F$3:$F$239,J9,$H$3:$H$239) -> 2
B10: 4 | C10: Administración y apoyo general | D10: C.3.6.1.3 | E10: SALA DE ESPERA | F10: 201002 | G10: Mesa Lateral | H10: 5 | J10: 201004 | K10: Mesa Párvulo Tipo I | L10: =+SUMIF($F$3:$F$239,J10,$H$3:$H$239) -> 1
B11: 4 | C11: Administración y apoyo general | D11: C.3.6.1.31.3 | E11: COORDINADOR NEONATOLOGÍA | F11: 201001B | G11: Escritorio en L administrativo | H11: 1 | J11: 201011A | K11: Mesa Tipo Casino | L11: =+SUMIF($F$3:$F$239,J11,$H$3:$H$239) -> 2
B12: 4 | C12: Administración y apoyo general | D12: C.3.6.1.31.3 | E12: COORDINADOR NEONATOLOGÍA | F12: 203016A | G12: Mueble Tipo Biblioteca M45_A | H12: 1 | J12: TOTAL | L12: =SUM(L4:L11) -> 79
B13: 4 | C13: Administración y apoyo general | D13: C.3.6.1.41.1 | E13: ESTAR PERSONAL C/ KITCHENETTE | F13: 201011B | G13: Mesa Tipo Casino Redonda 90 cm | H13: 1
B14: 4 | C14: Administración y apoyo general | D14: C.3.6.1.41.2 | E14: ESTAR PERSONAL C/ KITCHENETTE | F14: 201011B | G14: Mesa Tipo Casino Redonda 90 cm | H14: 1
B15: 4 | C15: Administración y apoyo general | D15: C.3.6.1.6 | E15: SALA DE ESTAR FAMILIARES Y ENTREVISTAS | F15: 201002 | G15: Mesa Lateral | H15: 1
B16: 4 | C16: Administración y apoyo general | D16: C.3.6.1.6 | E16: SALA DE ESTAR FAMILIARES Y ENTREVISTAS | F16: 201011B | G16: Mesa Tipo Casino Redonda 90 cm | H16: 1
B17: 4 | C17: Chile Crece Contigo | D17: C.3.6.1.10 | E17: SALA TALLER CHILE CRECE CONTIGO | F17: 201008 | G17: Mesa Reuniones Tipo I | H17: 1
B18: 4 | C18: Hospitalización | D18: C.3.6.1.9 | E18: OFICINA CHILE CRECE CONTIGO | F18: 201001A | G18: Escritorio simple 120x70 cm | H18: 2
B19: 4 | C19: Hospitalización | D19: C.3.6.1.9 | E19: OFICINA CHILE CRECE CONTIGO | F19: 203016A | G19: Mueble Tipo Biblioteca M45_A | H19: 2
B20: 4 | C20: Neonatología | D20: C.3.6.1.30.1 | E20: SALA DE ENTREVISTAS | F20: 201001B | G20: Escritorio en L administrativo | H20: 1
B21: 4 | C21: Neonatología | D21: C.3.6.1.30.1 | E21: SALA DE ENTREVISTAS | F21: 203016A | G21: Mueble Tipo Biblioteca M45_A | H21: 1
B22: 4 | C22: Neonatología | D22: C.3.8.2.1 | E22: ESTAR PERSONAL C/ KITCHENETTE | F22: 201011B | G22: Mesa Tipo Casino Redonda 90 cm | H22: 1
B23: 4 | C23: SEDILE | D23: C.5.8.1.2.1 | E23: OFICINA NUTRICIONISTA | F23: 201001A | G23: Escritorio simple 120x70 cm | H23: 1
B24: 4 | C24: SEDILE | D24: C.5.8.1.2.1 | E24: OFICINA NUTRICIONISTA | F24: 203016A | G24: Mueble Tipo Biblioteca M45_A | H24: 1
B25: 4 | C25: SEDILE | D25: C.5.8.1.2.2 | E25: ESTAR PERSONAL C/ KITCHENETTE | F25: 201011B | G25: Mesa Tipo Casino Redonda 90 cm | H25: 1
B26: 5 | C26: Administración y apoyo general | D26: C.3.4.2.1 | E26: SALA DE ESPERA | F26: 201002 | G26: Mesa Lateral | H26: 3
B27: 5 | C27: Administración y apoyo general | D27: C.3.4.2.19 | E27: ESTAR PERSONAL C/ KITCHENETTE | F27: 201011B | G27: Mesa Tipo Casino Redonda 90 cm | H27: 1
B28: 5 | C28: Administración y apoyo general | D28: C.3.4.2.4 | E28: MÓDULO TRABAJO SUPERVISOR | F28: 201001A | G28: Escritorio simple 120x70 cm | H28: 3
B29: 5 | C29: Administración y apoyo general | D29: C.3.4.2.4 | E29: MÓDULO TRABAJO SUPERVISOR | F29: 203016A | G29: Mueble Tipo Biblioteca M45_A | H29: 3
B30: 5 | C30: Administración y apoyo general | D30: C.3.4.2.9 | E30: SALA MULTIUSO | F30: 201010 | G30: Mesa Reuniones Tipo III | H30: 1
B31: 5 | C31: Administración y apoyo general | D31: C.3.5.1 | E31: OFICINA JEFE MQ INFANTIL | F31: 201008 | G31: Mesa Reuniones Tipo I | H31: 1
B32: 5 | C32: Administración y apoyo general | D32: C.3.5.1 | E32: OFICINA JEFE MQ INFANTIL | F32: 201001B | G32: Escritorio en L administrativo | H32: 1
B33: 5 | C33: Administración y apoyo general | D33: C.3.5.1 | E33: OFICINA JEFE MQ INFANTIL | F33: 203016A | G33: Mueble Tipo Biblioteca M45_A | H33: 1
B34: 5 | C34: Administración y apoyo general | D34: C.3.5.10 | E34: MÓDULO TRABAJO SUPERVISOR | F34: 201001A | G34: Escritorio simple 120x70 cm | H34: 1
B35: 5 | C35: Administración y apoyo general | D35: C.3.5.10 | E35: MÓDULO TRABAJO SUPERVISOR | F35: 203016A | G35: Mueble Tipo Biblioteca M45_A | H35: 1
B36: 5 | C36: Administración y apoyo general | D36: C.3.5.31 | E36: ESTAR PERSONAL C/ KITCHENETTE | F36: 201011B | G36: Mesa Tipo Casino Redonda 90 cm | H36: 1
B37: 5 | C37: Administración y apoyo general | D37: C.3.5.34 | E37: AULA HOSPITALARIA | F37: 201004 | G37: Mesa Párvulo Tipo I | H37: 1
B38: 5 | C38: Administración y apoyo general | D38: C.3.5.34 | E38: AULA HOSPITALARIA | F38: 201008 | G38: Mesa Reuniones Tipo I | H38: 1
B39: 5 | C39: Administración y apoyo general | D39: C.3.5.4 | E39: SALA DE ESPERA | F39: 201002 | G39: Mesa Lateral | H39: 2
B40: 5 | C40: Administración y apoyo general | D40: C.3.5.7 | E40: SALA DE ESTAR FAMILIARES Y ENTREVISTAS | F40: 201002 | G40: Mesa Lateral | H40: 1
B41: 5 | C41: Administración y apoyo general | D41: C.3.5.7 | E41: SALA DE ESTAR FAMILIARES Y ENTREVISTAS | F41: 201011B | G41: Mesa Tipo Casino Redonda 90 cm | H41: 1
...

Sheet Acumulado
B2: Despacho | C2: Piso | D2: Servicio | E2: Codigo de recinto referencial | F2: Nombre Recinto | G2: Tipo Equipo/ Mobiliario | H2: Nombre | I2: Cantidad | K2: Nombre | L2: Tipo Equipo/ Mobiliario | M2: Cantidad
B3: 1 | C3: 1 | D3: Diálisis | E3: C.2.3.1 | F3: OFICINA JEFE DIÁLISIS | G3: 201001B | H3: Escritorio en L administrativo | I3: 1 | K3: {=+_xlfn.UNIQUE(H3:H644)} -> Escritorio en L administrativo | L3: =+_xlfn.XLOOKUP(K3,$H$3:$H$644,$G$3:$G$644) -> 201001B | M3: =+SUMIF($H$3:$H$644,K3,$I$3:$I$644) -> 172
B4: 1 | C4: 1 | D4: Diálisis | E4: C.2.3.1 | F4: OFICINA JEFE DIÁLISIS | G4: 203016A | H4: Mueble Tipo Biblioteca M45_A | I4: 1 | K4: Mueble Tipo Biblioteca M45_A | L4: =+_xlfn.XLOOKUP(K4,$H$3:$H$644,$G$3:$G$644) -> 203016A | M4: =+SUMIF($H$3:$H$580,K4,$I$3:$I$580) -> 243
B5: 1 | C5: 1 | D5: Diálisis | E5: C.2.3.12 | F5: BOX EVALUACIÓN | G5: 201001C | H5: Escritorio de Consultas | I5: 1 | K5: Escritorio de Consultas | L5: =+_xlfn.XLOOKUP(K5,$H$3:$H$644,$G$3:$G$644) -> 201001C | M5: =+SUMIF($H$3:$H$580,K5,$I$3:$I$580) -> 53
B6: 1 | C6: 1 | D6: Diálisis | E6: C.2.3.13.1 | F6: PUESTO DIALISADOS CRÓNICOS | G6: 201001A | H6: Escritorio simple 120x70 cm | I6: 1 | K6: Escritorio simple 120x70 cm | L6: =+_xlfn.XLOOKUP(K6,$H$3:$H$644,$G$3:$G$644) -> 201001A | M6: =+SUMIF($H$3:$H$580,K6,$I$3:$I$580) -> 109
B7: 1 | C7: 1 | D7: Diálisis | E7: C.2.3.13.2 | F7: PUESTO DIALISADOS CRÓNICOS | G7: 201001A | H7: Escritorio simple 120x70 cm | I7: 1 | K7: Mesa Reuniones Tipo I | L7: =+_xlfn.XLOOKUP(K7,$H$3:$H$644,$G$3:$G$644) -> 201008 | M7: =+SUMIF($H$3:$H$580,K7,$I$3:$I$580) -> 44
B8: 1 | C8: 1 | D8: Diálisis | E8: C.2.3.13.3 | F8: PUESTO DIALISADOS CRÓNICOS | G8: 201001A | H8: Escritorio simple 120x70 cm | I8: 1 | K8: Mesa Párvulo Tipo I | L8: =+_xlfn.XLOOKUP(K8,$H$3:$H$644,$G$3:$G$644) -> 201004 | M8: =+SUMIF($H$3:$H$580,K8,$I$3:$I$580) -> 7
B9: 1 | C9: 1 | D9: Diálisis | E9: C.2.3.19 | F9: SALA POST-DIALISADOS | G9: 201008 | H9: Mesa Reuniones Tipo I | I9: 1 | K9: Mesa Reuniones Tipo III | L9: =+_xlfn.XLOOKUP(K9,$H$3:$H$644,$G$3:$G$644) -> 201010 | M9: =+SUMIF($H$3:$H$580,K9,$I$3:$I$580) -> 10
B10: 1 | C10: 1 | D10: Diálisis | E10: C.2.3.2 | F10: OFICINA ENFERMERA COORDINADORA (PERITONEO) | G10: 201001A | H10: Escritorio simple 120x70 cm | I10: 1 | K10: Mesa Tipo Casino Circular | L10: =+_xlfn.XLOOKUP(K10,$H$3:$H$644,$G$3:$G$644) -> 201011A | M10: =+SUMIF($H$3:$H$580,K10,$I$3:$I$580) -> 69
B11: 1 | C11: 1 | D11: Diálisis | E11: C.2.3.2 | F11: OFICINA ENFERMERA COORDINADORA (PERITONEO) | G11: 203016A | H11: Mueble Tipo Biblioteca M45_A | I11: 1 | K11: Mesa Lateral | L11: =+_xlfn.XLOOKUP(K11,$H$3:$H$644,$G$3:$G$644) -> 201002 | M11: =+SUMIF($H$3:$H$580,K11,$I$3:$I$580) -> 6
B12: 1 | C12: 1 | D12: Diálisis | E12: C.2.3.39 | F12: OFICINA COORDINADORA (HEMODIALISIS) | G12: 201001B | H12: Escritorio en L administrativo | I12: 1 | K12: Mesa Párvulo Tipo II | L12: =+_xlfn.XLOOKUP(K12,$H$3:$H$644,$G$3:$G$644) -> 201005 | M12: =+SUMIF($H$3:$H$580,K12,$I$3:$I$580) -> 12
B13: 1 | C13: 1 | D13: Diálisis | E13: C.2.3.39 | F13: OFICINA COORDINADORA (HEMODIALISIS) | G13: 203016A | H13: Mueble Tipo Biblioteca M45_A | I13: 1 | K13: Mueble Locker | L13: =+_xlfn.XLOOKUP(K13,$H$3:$H$644,$G$3:$G$644) -> 202012 | M13: =+SUMIF($H$3:$H$580,K13,$I$3:$I$580) -> 8
B14: 1 | C14: 1 | D14: Diálisis | E14: C.2.3.6 | F14: MESÓN DE RECEPCIÓN C/ARCHIVO Y FOTOCOPIADORA | G14: 203016A | H14: Mueble Tipo Biblioteca M45_A | I14: 1 | K14: Mesa Párvulo Inclusión | L14: =+_xlfn.XLOOKUP(K14,$H$3:$H$644,$G$3:$G$644) -> 201003 | M14: =+SUMIF($H$3:$H$580,K14,$I$3:$I$580) -> 2
B15: 1 | C15: 1 | D15: Med física y rehabilitación | E15: C.5.7.1 | F15: MESÓN C/ARCHIVO Y FOTOCOPIADORA | G15: 203016A | H15: Mueble Tipo Biblioteca M45_A | I15: 1 | K15: Mesa Reuniones Tipo II | L15: =+_xlfn.XLOOKUP(K15,$H$3:$H$644,$G$3:$G$644) -> 201009 | M15: =+SUMIF($H$3:$H$580,K15,$I$3:$I$580) -> 16
B16: 1 | C16: 1 | D16: Med física y rehabilitación | E16: C.5.7.15 | F16: GIMNASIO PEDIATRICO | G16: 201004 | H16: Mesa Párvulo Tipo I | I16: 1 | K16: Mesa Tipo Casino Redonda 90 cm | L16: =+_xlfn.XLOOKUP(K16,$H$3:$H$644,$G$3:$G$644) -> 201011B | M16: =+SUMIF($H$3:$H$580,K16,$I$3:$I$580) -> 17
B17: 1 | C17: 1 | D17: Med física y rehabilitación | E17: C.5.7.18 | F17: SALA DE TERAPIA GRUPAL (12 MAX) | G17: 201010 | H17: Mesa Reuniones Tipo III | I17: 1 | K17: Punto de registro clínico | L17: =+_xlfn.XLOOKUP(K17,$H$3:$H$644,$G$3:$G$644) -> 201001E | M17: =+SUMIF($H$3:$H$580,K17,$I$3:$I$580) -> 31
B18: 1 | C18: 1 | D18: Med física y rehabilitación | E18: C.5.7.18 | F18: SALA DE TERAPIA GRUPAL (12 MAX) | G18: 201001A | H18: Escritorio simple 120x70 cm | I18: 1 | K18: Escritorio simple 130x70 cm | L18: =+_xlfn.XLOOKUP(K18,$H$3:$H$644,$G$3:$G$644) -> 201001D | M18: =+SUMIF($H$3:$H$580,K18,$I$3:$I$580) -> 4
B19: 1 | C19: 1 | D19: Med física y rehabilitación | E19: C.5.7.19 | F19: SALA TERÁPIA OCUP. ADULTO E INFANTIL | G19: 201008 | H19: Mesa Reuniones Tipo I | I19: 3 | K19: Mueble Tipo Biblioteca M45_B | L19: =+_xlfn.XLOOKUP(K19,$H$3:$H$644,$G$3:$G$644) -> 203016B | M19: =+SUMIF($H$3:$H$580,K19,$I$3:$I$580) -> 16
B20: 1 | C20: 1 | D20: Med física y rehabilitación | E20: C.5.7.19 | F20: SALA TERÁPIA OCUP. ADULTO E INFANTIL | G20: 203016A | H20: Mueble Tipo Biblioteca M45_A | I20: 1 | M20: =SUM(M3:M19) -> 819
B21: 1 | C21: 1 | D21: Med física y rehabilitación | E21: C.5.7.20 | F21: SALA DE ACTIVDAD DE LA VIDA DIARIA C/BAÑO DE INSTRUCCIÓN | G21: 201011A | H21: Mesa Tipo Casino Circular | I21: 1
B22: 1 | C22: 1 | D22: Med física y rehabilitación | E22: C.5.7.21 | F22: OFICINA JEFE REHABILITACIÓN | G22: 201001B | H22: Escritorio en L administrativo | I22: 1
B23: 1 | C23: 1 | D23: Med física y rehabilitación | E23: C.5.7.21 | F23: OFICINA JEFE REHABILITACIÓN | G23: 203016A | H23: Mueble Tipo Biblioteca M45_A | I23: 1
B24: 1 | C24: 1 | D24: Med física y rehabilitación | E24: C.5.7.22 | F24: OFICINA JEFE COORDINADOR | G24: 201001B | H24: Escritorio en L administrativo | I24: 1
B25: 1 | C25: 1 | D25: Med física y rehabilitación | E25: C.5.7.22 | F25: OFICINA JEFE COORDINADOR | G25: 203016A | H25: Mueble Tipo Biblioteca M45_A | I25: 1
B26: 1 | C26: 1 | D26: Med física y rehabilitación | E26: C.5.7.23 | F26: SALA MULTIUSO | G26: 203016A | H26: Mueble Tipo Biblioteca M45_A | I26: 1
B27: 1 | C27: 1 | D27: Med física y rehabilitación | E27: C.5.7.4.1 | F27: BOX KINESIOLOGO(1) | G27: 201001C | H27: Escritorio de Consultas | I27: 1
B28: 1 | C28: 1 | D28: Med física y rehabilitación | E28: C.5.7.4.2 | F28: BOX PSICOLOGO / A. SOCIAL | G28: 201001C | H28: Escritorio de Consultas | I28: 1
B29: 1 | C29: 1 | D29: Med física y rehabilitación | E29: C.5.7.4.2 | F29: BOX PSICOLOGO / A. SOCIAL | G29: 203016A | H29: Mueble Tipo Biblioteca M45_A | I29: 1
B30: 1 | C30: 1 | D30: Med física y rehabilitación | E30: C.5.7.5.1 | F30: BOX INDIFERENCIADO (FONOAUDIO Y TERAPIA OCU)(1) | G30: 201001C | H30: Escritorio de Consultas | I30: 1
B31: 1 | C31: 1 | D31: Med física y rehabilitación | E31: C.5.7.5.2 | F31: BOX INDIFERENCIADO (FONOAUDIO Y TERAPIA OCU)(2) | G31: 201001C | H31: Escritorio de Consultas | I31: 1
B32: 1 | C32: 1 | D32: Med física y rehabilitación | E32: C.5.7.5.2.1 | F32: BOX FONOAUDIO PEDIATRICO | G32: 201004 | H32: Mesa Párvulo Tipo I | I32: 1
B33: 1 | C33: 1 | D33: Med física y rehabilitación | E33: C.5.7.5.2.1 | F33: BOX FONOAUDIO PEDIATRICO | G33: 201001C | H33: Escritorio de Consultas | I33: 1
B34: 1 | C34: 1 | D34: Morgue | E34: C.5.9.2 | F34: ESPACIO PARA DEUDOS | G34: 201002 | H34: Mesa Lateral | I34: 1
B35: 1 | C35: 1 | D35: Morgue | E35: C.5.9.5 | F35: MESÓN RECEPCIÓN DE REGISTRO DE INFORMES | G35: 201001B | H35: Escritorio en L administrativo | I35: 1
B36: 1 | C36: 1 | D36: Morgue | E36: C.5.9.5 | F36: MESÓN RECEPCIÓN DE REGISTRO DE INFORMES | G36: 203016A | H36: Mueble Tipo Biblioteca M45_A | I36: 1
B37: 1 | C37: 1 | D37: Morgue | E37: C.5.9.7 | F37: VESTIDOR Y ENTREGA FAMILIARES | G37: 201001A | H37: Escritorio simple 120x70 cm | I37: 1
B38: 2 | C38: 1 | D38: Abastecimiento | E38: D.3.3.3.1 | F38: COORDINADOR BODEGA | G38: 201001B | H38: Escritorio en L administrativo | I38: 1
B39: 2 | C39: 1 | D39: Abastecimiento | E39: D.3.3.3.1 | F39: COORDINADOR BODEGA | G39: 203016A | H39: Mueble Tipo Biblioteca M45_A | I39: 1
B40: 2 | C40: 1 | D40: Abastecimiento | E40: D.3.3.3.10 | F40: ESTAR PERSONAL C/ KITCHENETTE | G40: 201011A | H40: Mesa Tipo Casino Circular | I40: 1
B41: 2 | C41: 1 | D41: Abastecimiento | E41: D.3.3.3.11 | F41: ÁREA REGISTRO BODEGA GENERAL | G41: 201001A | H41: Escritorio simple 120x70 cm | I41: 1
...

Sheet Detalle
O1: Suma de Cantidad | Q1: Piso | Z1: En obra | AB1: Restante | AD1: %
B2: Despacho | C2: Piso | D2: Servicio | E2: Codigo de recinto referencial | F2: Nombre Recinto | G2: Tipo Equipo/ Mobiliario | H2: Nombre | I2: Cantidad | K2: Nombre | L2: Tipo Equipo/ Mobiliario | M2: Cantidad | O2: Tipo Equipo/ Mobiliario | P2: Nombre | Q2: 1 | R2: 2 | S2: 3 | T2: 4 | U2: 5 | V2: 6 | W2: 7 | X2: Total general
B3: 1 | C3: 1 | D3: Diálisis | E3: C.2.3.1 | F3: OFICINA JEFE DIÁLISIS | G3: 201001B | H3: Escritorio en L administrativo | I3: 1 | K3: {=+_xlfn.UNIQUE(H3:H162)} -> Escritorio en L administrativo | L3: =+_xlfn.XLOOKUP(K3,$H$3:$H$162,$G$3:$G$162) -> 201001B | M3: =+SUMIF($H$3:$H$162,K3,$I$3:$I$162) -> 33 | O3: 204012 | P3: Silla Visita | Q3: 361 | R3: 488 | S3: 302 | T3: 42 | U3: 30 | V3: 33 | W3: 9 | X3: 1265 | Z3: =IFERROR(_xlfn.XLOOKUP(O3,Acumulado!$L$3:$L$19,Acumulado!$M$3:$M$19),"0") -> 0 | AB3: =+X3-Z3 -> 1265 | AD3: =1-(AB3/X3) -> 0
B4: 1 | C4: 1 | D4: Diálisis | E4: C.2.3.1 | F4: OFICINA JEFE DIÁLISIS | G4: 203016A | H4: Mueble Tipo Biblioteca M45_A | I4: 1 | K4: Mueble Tipo Biblioteca M45_A | L4: =+_xlfn.XLOOKUP(K4,$H$3:$H$162,$G$3:$G$162) -> 203016A | M4: =+SUMIF($H$3:$H$162,K4,$I$3:$I$162) -> 65 | O4: 204006C | P4: Silla Ergonómica | Q4: 149 | R4: 185 | S4: 138 | T4: 24 | U4: 18 | V4: 18 | W4: 16 | X4: 548 | Z4: =IFERROR(_xlfn.XLOOKUP(O4,Acumulado!$L$3:$L$19,Acumulado!$M$3:$M$19),"0") -> 0 | AB4: =+X4-Z4 -> 548 | AD4: =1-(AB4/X4) -> 0
B5: 1 | C5: 1 | D5: Diálisis | E5: C.2.3.12 | F5: BOX EVALUACIÓN | G5: 201001C | H5: Escritorio de Consultas | I5: 1 | K5: Escritorio de Consultas | L5: =+_xlfn.XLOOKUP(K5,$H$3:$H$162,$G$3:$G$162) -> 201001C | M5: =+SUMIF($H$3:$H$162,K5,$I$3:$I$162) -> 13 | O5: 204010 | P5: Silla tipo Casino | Q5: 114 | R5: 300 | S5: 28 | T5: 20 | U5: 12 | V5: 12 | W5: 12 | X5: 498 | Z5: =IFERROR(_xlfn.XLOOKUP(O5,Acumulado!$L$3:$L$19,Acumulado!$M$3:$M$19),"0") -> 0 | AB5: =+X5-Z5 -> 498 | AD5: =1-(AB5/X5) -> 0
B6: 1 | C6: 1 | D6: Diálisis | E6: C.2.3.13.1 | F6: PUESTO DIALISADOS CRÓNICOS | G6: 201001A | H6: Escritorio simple 120x70 cm | I6: 1 | K6: Escritorio simple 120x70 cm | L6: =+_xlfn.XLOOKUP(K6,$H$3:$H$162,$G$3:$G$162) -> 201001A | M6: =+SUMIF($H$3:$H$162,K6,$I$3:$I$162) -> 37 | O6: 203016A | P6: Mueble Tipo Biblioteca M45_A | Q6: 74 | R6: 76 | S6: 102 | T6: 8 | U6: 5 | V6: 4 | W6: 4 | X6: 273 | Z6: =IFERROR(_xlfn.XLOOKUP(O6,Acumulado!$L$3:$L$19,Acumulado!$M$3:$M$19),"0") -> 243 | AB6: =+X6-Z6 -> 30 | AD6: =1-(AB6/X6) -> 0.89010989
B7: 1 | C7: 1 | D7: Diálisis | E7: C.2.3.13.2 | F7: PUESTO DIALISADOS CRÓNICOS | G7: 201001A | H7: Escritorio simple 120x70 cm | I7: 1 | K7: Mesa Reuniones Tipo I | L7: =+_xlfn.XLOOKUP(K7,$H$3:$H$162,$G$3:$G$162) -> 201008 | M7: =+SUMIF($H$3:$H$162,K7,$I$3:$I$162) -> 14 | O7: 204020 | P7: Silla Butaca Espera 3 Cuerpos | Q7: 100 | R7: 96 | S7: 38 | V7: 4 | X7: 238 | Z7: =IFERROR(_xlfn.XLOOKUP(O7,Acumulado!$L$3:$L$19,Acumulado!$M$3:$M$19),"0") -> 0 | AB7: =+X7-Z7 -> 238 | AD7: =1-(AB7/X7) -> 0
B8: 1 | C8: 1 | D8: Diálisis | E8: C.2.3.13.3 | F8: PUESTO DIALISADOS CRÓNICOS | G8: 201001A | H8: Escritorio simple 120x70 cm | I8: 1 | K8: Mesa Párvulo Tipo I | L8: =+_xlfn.XLOOKUP(K8,$H$3:$H$162,$G$3:$G$162) -> 201004 | M8: =+SUMIF($H$3:$H$162,K8,$I$3:$I$162) -> 3 | O8: 204015 | P8: Sillón Bergere | Q8: 5 | R8: 1 | S8: 14 | T8: 38 | U8: 28 | V8: 44 | W8: 55 | X8: 185 | Z8: =IFERROR(_xlfn.XLOOKUP(O8,Acumulado!$L$3:$L$19,Acumulado!$M$3:$M$19),"0") -> 0 | AB8: =+X8-Z8 -> 185 | AD8: =1-(AB8/X8) -> 0
B9: 1 | C9: 1 | D9: Diálisis | E9: C.2.3.19 | F9: SALA POST-DIALISADOS | G9: 201008 | H9: Mesa Reuniones Tipo I | I9: 1 | K9: Mesa Reuniones Tipo III | L9: =+_xlfn.XLOOKUP(K9,$H$3:$H$162,$G$3:$G$162) -> 201010 | M9: =+SUMIF($H$3:$H$162,K9,$I$3:$I$162) -> 2 | O9: 201001B | P9: Escritorio en L administrativo | Q9: 38 | R9: 47 | S9: 82 | T9: 5 | U9: 1 | V9: 4 | X9: 177 | Z9: =IFERROR(_xlfn.XLOOKUP(O9,Acumulado!$L$3:$L$19,Acumulado!$M$3:$M$19),"0") -> 172 | AB9: =+X9-Z9 -> 5 | AD9: =1-(AB9/X9) -> 0.97175141
B10: 1 | C10: 1 | D10: Diálisis | E10: C.2.3.2 | F10: OFICINA ENFERMERA COORDINADORA (PERITONEO) | G10: 201001A | H10: Escritorio simple 120x70 cm | I10: 1 | K10: Mesa Tipo Casino Circular | L10: =+_xlfn.XLOOKUP(K10,$H$3:$H$162,$G$3:$G$162) -> 201011A | M10: =+SUMIF($H$3:$H$162,K10,$I$3:$I$162) -> 10 | O10: 201001A | P10: Escritorio simple 120x70 cm | Q10: 37 | R10: 52 | S10: 20 | T10: 3 | U10: 4 | V10: 2 | W10: 4 | X10: 122 | Z10: =IFERROR(_xlfn.XLOOKUP(O10,Acumulado!$L$3:$L$19,Acumulado!$M$3:$M$19),"0") -> 109 | AB10: =+X10-Z10 -> 13 | AD10: =1-(AB10/X10) -> 0.89344262
B11: 1 | C11: 1 | D11: Diálisis | E11: C.2.3.2 | F11: OFICINA ENFERMERA COORDINADORA (PERITONEO) | G11: 203016A | H11: Mueble Tipo Biblioteca M45_A | I11: 1 | K11: Mesa Lateral | L11: =+_xlfn.XLOOKUP(K11,$H$3:$H$162,$G$3:$G$162) -> 201002 | M11: =+SUMIF($H$3:$H$162,K11,$I$3:$I$162) -> 2 | O11: 204014 | P11: Sillón 2 Cuerpo | Q11: 22 | R11: 13 | S11: 14 | T11: 13 | U11: 13 | V11: 14 | W11: 14 | X11: 103 | Z11: =IFERROR(_xlfn.XLOOKUP(O11,Acumulado!$L$3:$L$19,Acumulado!$M$3:$M$19),"0") -> 0 | AB11: =+X11-Z11 -> 103 | AD11: =1-(AB11/X11) -> 0
B12: 1 | C12: 1 | D12: Diálisis | E12: C.2.3.39 | F12: OFICINA COORDINADORA (HEMODIALISIS) | G12: 201001B | H12: Escritorio en L administrativo | I12: 1 | K12: Mesa Párvulo Tipo II | L12: =+_xlfn.XLOOKUP(K12,$H$3:$H$162,$G$3:$G$162) -> 201005 | M12: =+SUMIF($H$3:$H$162,K12,$I$3:$I$162) -> 12 | O12: 201011A | P12: Mesa Tipo Casino Circular | Q12: 12 | R12: 57 | S12: 2 | V12: 1 | W12: 1 | X12: 73 | Z12: =IFERROR(_xlfn.XLOOKUP(O12,Acumulado!$L$3:$L$19,Acumulado!$M$3:$M$19),"0") -> 69 | AB12: =+X12-Z12 -> 4 | AD12: =1-(AB12/X12) -> 0.94520548
B13: 1 | C13: 1 | D13: Diálisis | E13: C.2.3.39 | F13: OFICINA COORDINADORA (HEMODIALISIS) | G13: 203016A | H13: Mueble Tipo Biblioteca M45_A | I13: 1 | K13: Mueble Locker | L13: =+_xlfn.XLOOKUP(K13,$H$3:$H$162,$G$3:$G$162) -> 202012 | M13: =+SUMIF($H$3:$H$162,K13,$I$3:$I$162) -> 8 | O13: 201001E | P13: Punto de registro clínico | Q13: 28 | R13: 21 | S13: 10 | T13: 3 | U13: 3 | V13: 1 | W13: 1 | X13: 67 | Z13: =IFERROR(_xlfn.XLOOKUP(O13,Acumulado!$L$3:$L$19,Acumulado!$M$3:$M$19),"0") -> 31 | AB13: =+X13-Z13 -> 36 | AD13: =1-(AB13/X13) -> 0.46268657
B14: 1 | C14: 1 | D14: Diálisis | E14: C.2.3.6 | F14: MESÓN DE RECEPCIÓN C/ARCHIVO Y FOTOCOPIADORA | G14: 203016A | H14: Mueble Tipo Biblioteca M45_A | I14: 1 | K14: Mesa Párvulo Inclusión | L14: =+_xlfn.XLOOKUP(K14,$H$3:$H$162,$G$3:$G$162) -> 201003 | M14: =+SUMIF($H$3:$H$162,K14,$I$3:$I$162) -> 2 | O14: 204006A | P14: Silla Ergonómica Reforzada | Q14: 17 | R14: 16 | S14: 21 | T14: 3 | U14: 1 | V14: 1 | W14: 1 | X14: 60 | Z14: =IFERROR(_xlfn.XLOOKUP(O14,Acumulado!$L$3:$L$19,Acumulado!$M$3:$M$19),"0") -> 0 | AB14: =+X14-Z14 -> 60 | AD14: =1-(AB14/X14) -> 0
